# MODULE 2 - Week 5 Promises

## TOPICS
- [x] Callbacks Review
- [x] Try Catch
- [x] Promises (`then` what?)
- [x] PromiseAll
- [x] Callback Hell

[Documentation here](https://developer.mozilla.org/en-US/docs/Web/JavaScript/Reference/Global_Objects/Promise)
If you're looking for a full recording, please visit [this link](https://vimeo.com/801793554/89cb3b42ad?embedded=true&source=video_title&owner=147384195)

## Error handling & exceptions

- Any thrown or unhandled error will cause the app to crash

```javascript
const someFct = () => {
	console.log("Executing someFct");
	// This will throw a reference error
	undeclared;
};
someFct();
console.log("After executing someFct...");
```

- `console.log('After executing someFct...')` never gets executed
- Just because there is an error doesn't mean the app should crashed

### Try Catch

- A _try catch_ will gracefully handle the error

```javascript
const someFct = () => {
	console.log("Executing someFct");
	// This will throw a reference error
	undeclared;
};

try {
	someFct();
} catch (error) {
	console.log(error);
} finally {
	console.log("finally done");
}

console.log("after executing someFtc...");
```

- The benefit is that it doesn't stop the flow of excution
- When an error occurs, JavaScript generates an object containing the details about it. The object is then passed as an argument to catch
- `finally` always get executed whether there is an exception or not. Good for closing connections or files for example.

- For all built-in errors, the error object inside catch block has a few properties:

  - name -> Name of the error
  - message -> Textual message about error details.
  - stack -> Error stack trace

```javascript
try {
	someFct();
} catch (error) {
	console.log(`Catched Error: ${error.name} ${error.message}`);
} finally {
	console.log("finally done");
}
```

### One Small Problem With Try Catch

- There is caveat with `try catch` clause. It works for synchronous code but not async code!

- Catch block is not there when asynchronous code is executed

```js
const someAsyncFct = () => {
	console.log("async, taking 3 seconds...");
	setTimeout(() => {
		throw new Error();
	}, 3000);
};

try {
	someAsyncFct();
} catch (e) {
	// not catching the error
	console.log("trying to catch the error: ", e.message);
} finally {
	console.log("This is executed way before the error is thrown");
}
```

### Using a tradional callbacks

```javascript
const upperCaseAsync = (inputStr, cb) => {
	console.log("async, taking 3 seconds...");
	setTimeout(() => {
		cb(null, inputStr.toUpperCase());
	}, 3000);
};

upperCaseAsync("Hello Bob!", (err, str) => {
	if (err) {
		console.log("Error");
		return;
	}
	console.log(str);
});
```

- Using multiple callbacks, we get into `callback hell!`

```javascript
const getUser = (cb) => {
	console.log("Getting the user, 2 seconds...");
	setTimeout(() => {
		cb(null, {
			name: "Bob Squarepants",
			email: "bob@squarepants.com",
		});
	}, 2000);
};

const upperCaseAsync = (inputStr, cb) => {
	console.log("async, taking 2 seconds...");
	setTimeout(() => {
		cb(null, inputStr.toUpperCase());
	}, 3000);
};

const sayHello = () => {
	getUser((err, user) => {
		console.log(user);
		if (err) {
			console.log("Error getting the user!");
			return;
		}
		upperCaseAsync(`Hello ${user.name}`, (err, str) => {
			if (err) {
				console.log("Error, cannot print hello message!");
				return;
			}
			console.log(str);
		});
	});
};

sayHello();
```

- Code is much harder to read
- More callback nesting means more trouble
- Using promises is resolving the issue.

## Promises

- Promises suggest a better syntax to handle callbacks
- Callbacks cannot catch errors with try catch
- Multiple callbacks call lead to callback hell